# Logfile created on 2016-10-31 13:52:57 +0000 by logger.rb/53141
I, [2016-10-31T13:52:57.462669 #7500]  INFO -- : *** below you find the most recent exception thrown, this will be likely (but not certainly) the exception that made the application exit abnormally ***
E, [2016-10-31T13:52:57.462869 #7500] ERROR -- : -ERR [SYS/TEMP] Temporary system problem. Please try again later. (Net::POPAuthenticationError)
/usr/local/rvm/rubies/ruby-2.3.0/lib/ruby/2.3.0/net/pop.rb:1006:in `check_response_auth'
/usr/local/rvm/rubies/ruby-2.3.0/lib/ruby/2.3.0/net/pop.rb:905:in `auth'
/usr/local/rvm/rubies/ruby-2.3.0/lib/ruby/2.3.0/net/pop.rb:567:in `do_start'
/usr/local/rvm/rubies/ruby-2.3.0/lib/ruby/2.3.0/net/pop.rb:537:in `start'
/usr/local/rvm/gems/ruby-2.3.0/gems/mailman-0.7.0/lib/mailman/receiver/pop3.rb:31:in `connect'
/usr/local/rvm/gems/ruby-2.3.0/gems/mailman-0.7.0/lib/mailman/application.rb:132:in `block in polling_loop'
/usr/local/rvm/gems/ruby-2.3.0/gems/mailman-0.7.0/lib/mailman/application.rb:130:in `loop'
/usr/local/rvm/gems/ruby-2.3.0/gems/mailman-0.7.0/lib/mailman/application.rb:130:in `polling_loop'
/usr/local/rvm/gems/ruby-2.3.0/gems/mailman-0.7.0/lib/mailman/application.rb:83:in `run'
/usr/local/rvm/gems/ruby-2.3.0/gems/mailman-0.7.0/lib/mailman/application.rb:11:in `run'
/home/ubuntu/project/remindme1/scripts/mailman_server.rb:19:in `<top (required)>'
/usr/local/rvm/gems/ruby-2.3.0/gems/daemons-1.2.4/lib/daemons/application.rb:219:in `load'
/usr/local/rvm/gems/ruby-2.3.0/gems/daemons-1.2.4/lib/daemons/application.rb:219:in `start_load'
/usr/local/rvm/gems/ruby-2.3.0/gems/daemons-1.2.4/lib/daemons/application.rb:298:in `start'
/usr/local/rvm/gems/ruby-2.3.0/gems/daemons-1.2.4/lib/daemons/application_group.rb:158:in `block (2 levels) in start_all'
/usr/local/rvm/gems/ruby-2.3.0/gems/daemons-1.2.4/lib/daemons/application_group.rb:157:in `fork'
/usr/local/rvm/gems/ruby-2.3.0/gems/daemons-1.2.4/lib/daemons/application_group.rb:157:in `block in start_all'
/usr/local/rvm/gems/ruby-2.3.0/gems/daemons-1.2.4/lib/daemons/application_group.rb:156:in `each'
/usr/local/rvm/gems/ruby-2.3.0/gems/daemons-1.2.4/lib/daemons/application_group.rb:156:in `start_all'
/usr/local/rvm/gems/ruby-2.3.0/gems/daemons-1.2.4/lib/daemons/controller.rb:66:in `run'
/usr/local/rvm/gems/ruby-2.3.0/gems/daemons-1.2.4/lib/daemons.rb:148:in `block in run'
/usr/local/rvm/gems/ruby-2.3.0/gems/daemons-1.2.4/lib/daemons/cmdline.rb:92:in `catch_exceptions'
/usr/local/rvm/gems/ruby-2.3.0/gems/daemons-1.2.4/lib/daemons.rb:147:in `run'
/home/ubuntu/project/remindme1/scripts/daemons/mailman_ctl.svc:13:in `<main>'
I, [2016-10-31T13:52:57.462976 #7500]  INFO -- : *** below you find all exception objects found in memory, some of them may have been thrown in your application, others may just be in memory because they are standard exceptions ***
E, [2016-10-31T13:52:57.463544 #7500] ERROR -- : stream closed (IOError)

E, [2016-10-31T13:52:57.463806 #7500] ERROR -- : failed to allocate memory (NoMemoryError)

E, [2016-10-31T13:52:57.463898 #7500] ERROR -- : stack level too deep (SystemStackError)

E, [2016-10-31T13:52:57.464306 #7500] ERROR -- : exception reentered (fatal)

E, [2016-10-31T13:52:57.493528 #7500] ERROR -- : No such file or directory @ rb_sysopen - /home/ubuntu/project/remindme1/scripts/mailman_server.rb.log (Errno::ENOENT)
/usr/local/rvm/rubies/ruby-2.3.0/lib/ruby/2.3.0/open-uri.rb:37:in `initialize'
/usr/local/rvm/rubies/ruby-2.3.0/lib/ruby/2.3.0/open-uri.rb:37:in `open'
/usr/local/rvm/rubies/ruby-2.3.0/lib/ruby/2.3.0/open-uri.rb:37:in `open'
/usr/local/rvm/rubies/ruby-2.3.0/lib/ruby/2.3.0/logger.rb:703:in `open_logfile'
/usr/local/rvm/rubies/ruby-2.3.0/lib/ruby/2.3.0/logger.rb:695:in `set_dev'
/usr/local/rvm/rubies/ruby-2.3.0/lib/ruby/2.3.0/logger.rb:635:in `initialize'
/usr/local/rvm/rubies/ruby-2.3.0/lib/ruby/2.3.0/logger.rb:353:in `new'
/usr/local/rvm/rubies/ruby-2.3.0/lib/ruby/2.3.0/logger.rb:353:in `initialize'
/usr/local/rvm/gems/ruby-2.3.0/gems/daemons-1.2.4/lib/daemons/application.rb:335:in `new'
/usr/local/rvm/gems/ruby-2.3.0/gems/daemons-1.2.4/lib/daemons/application.rb:335:in `exception_log'
/usr/local/rvm/gems/ruby-2.3.0/gems/daemons-1.2.4/lib/daemons/application.rb:181:in `block in start_load'
/usr/local/rvm/gems/ruby-2.3.0/gems/daemons-1.2.4/lib/daemons/application_group.rb:157:in `fork'
/usr/local/rvm/gems/ruby-2.3.0/gems/daemons-1.2.4/lib/daemons/application_group.rb:157:in `block in start_all'
/usr/local/rvm/gems/ruby-2.3.0/gems/daemons-1.2.4/lib/daemons/application_group.rb:156:in `each'
/usr/local/rvm/gems/ruby-2.3.0/gems/daemons-1.2.4/lib/daemons/application_group.rb:156:in `start_all'
/usr/local/rvm/gems/ruby-2.3.0/gems/daemons-1.2.4/lib/daemons/controller.rb:66:in `run'
/usr/local/rvm/gems/ruby-2.3.0/gems/daemons-1.2.4/lib/daemons.rb:148:in `block in run'
/usr/local/rvm/gems/ruby-2.3.0/gems/daemons-1.2.4/lib/daemons/cmdline.rb:92:in `catch_exceptions'
/usr/local/rvm/gems/ruby-2.3.0/gems/daemons-1.2.4/lib/daemons.rb:147:in `run'
/home/ubuntu/project/remindme1/scripts/daemons/mailman_ctl.svc:13:in `<main>'
E, [2016-10-31T13:52:57.493794 #7500] ERROR -- : -ERR [SYS/TEMP] Temporary system problem. Please try again later. (Net::POPAuthenticationError)
/usr/local/rvm/rubies/ruby-2.3.0/lib/ruby/2.3.0/net/pop.rb:1006:in `check_response_auth'
/usr/local/rvm/rubies/ruby-2.3.0/lib/ruby/2.3.0/net/pop.rb:905:in `auth'
/usr/local/rvm/rubies/ruby-2.3.0/lib/ruby/2.3.0/net/pop.rb:567:in `do_start'
/usr/local/rvm/rubies/ruby-2.3.0/lib/ruby/2.3.0/net/pop.rb:537:in `start'
/usr/local/rvm/gems/ruby-2.3.0/gems/mailman-0.7.0/lib/mailman/receiver/pop3.rb:31:in `connect'
/usr/local/rvm/gems/ruby-2.3.0/gems/mailman-0.7.0/lib/mailman/application.rb:132:in `block in polling_loop'
/usr/local/rvm/gems/ruby-2.3.0/gems/mailman-0.7.0/lib/mailman/application.rb:130:in `loop'
/usr/local/rvm/gems/ruby-2.3.0/gems/mailman-0.7.0/lib/mailman/application.rb:130:in `polling_loop'
/usr/local/rvm/gems/ruby-2.3.0/gems/mailman-0.7.0/lib/mailman/application.rb:83:in `run'
/usr/local/rvm/gems/ruby-2.3.0/gems/mailman-0.7.0/lib/mailman/application.rb:11:in `run'
/home/ubuntu/project/remindme1/scripts/mailman_server.rb:19:in `<top (required)>'
/usr/local/rvm/gems/ruby-2.3.0/gems/daemons-1.2.4/lib/daemons/application.rb:219:in `load'
/usr/local/rvm/gems/ruby-2.3.0/gems/daemons-1.2.4/lib/daemons/application.rb:219:in `start_load'
/usr/local/rvm/gems/ruby-2.3.0/gems/daemons-1.2.4/lib/daemons/application.rb:298:in `start'
/usr/local/rvm/gems/ruby-2.3.0/gems/daemons-1.2.4/lib/daemons/application_group.rb:158:in `block (2 levels) in start_all'
/usr/local/rvm/gems/ruby-2.3.0/gems/daemons-1.2.4/lib/daemons/application_group.rb:157:in `fork'
/usr/local/rvm/gems/ruby-2.3.0/gems/daemons-1.2.4/lib/daemons/application_group.rb:157:in `block in start_all'
/usr/local/rvm/gems/ruby-2.3.0/gems/daemons-1.2.4/lib/daemons/application_group.rb:156:in `each'
/usr/local/rvm/gems/ruby-2.3.0/gems/daemons-1.2.4/lib/daemons/application_group.rb:156:in `start_all'
/usr/local/rvm/gems/ruby-2.3.0/gems/daemons-1.2.4/lib/daemons/controller.rb:66:in `run'
/usr/local/rvm/gems/ruby-2.3.0/gems/daemons-1.2.4/lib/daemons.rb:148:in `block in run'
/usr/local/rvm/gems/ruby-2.3.0/gems/daemons-1.2.4/lib/daemons/cmdline.rb:92:in `catch_exceptions'
/usr/local/rvm/gems/ruby-2.3.0/gems/daemons-1.2.4/lib/daemons.rb:147:in `run'
/home/ubuntu/project/remindme1/scripts/daemons/mailman_ctl.svc:13:in `<main>'
